2023-08-16 11:30:53,971 - ERROR - Excepción no capturada:
Traceback (most recent call last):
  File "C:\Users\svcmerr\Desktop\pw\Conciliacion\run.py", line 12, in <module>
    menu_opciones.login()
  File "C:\Users\svcmerr\Desktop\pw\Conciliacion\menu_opciones.py", line 19, in login
    if  user_entry.get() == "admin" and password_entry.get() == "1234":
        ^^^^^^^^^^^^^^^^
  File "C:\Program Files\Python311\Lib\tkinter\__init__.py", line 3109, in get
    return self.tk.call(self._w, 'get')
           ^^^^^^^^^^^^^^^^^^^^^^^^^^^^
_tkinter.TclError: invalid command name ".!entry"
2023-08-16 11:31:26,488 - ERROR - Excepción no capturada:
Traceback (most recent call last):
  File "C:\Users\svcmerr\Desktop\pw\Conciliacion\run.py", line 12, in <module>
    menu_opciones.login()
  File "C:\Users\svcmerr\Desktop\pw\Conciliacion\menu_opciones.py", line 19, in login
    if  user_entry.get() == "admin" and password_entry.get() == "1234":
        ^^^^^^^^^^^^^^^^
  File "C:\Program Files\Python311\Lib\tkinter\__init__.py", line 3109, in get
    return self.tk.call(self._w, 'get')
           ^^^^^^^^^^^^^^^^^^^^^^^^^^^^
_tkinter.TclError: invalid command name ".!entry"
